<?xml version = "1.0"?>


<robot name = "pneumaticarm7r">
    <link name = "shoulderbase">
        <visual>
            <geometry>
                <box size="0.8350 0.08 0.08"/>
            </geometry>
            <material name="red">
                <color rgba="0.5 0 0 1"/>
            </material>
        </visual>
    </link>

    <link name = "shoulderlinkab">
         <visual>
            <geometry>
                 <cylinder length="0.105" radius="0.0325"/>
            </geometry>
            <material name="green">
                <color rgba="0 .9 0 1"/>
            </material>
        </visual>

    </link>

    <link name = "shoulderlinkfl">
         <visual>
            <geometry>
                <cylinder length="0.08" radius="0.04"/>
            </geometry>
            <material name="blue">
                <color rgba="0 0 .8 1"/>
            </material>
        </visual>

    </link>
   
   <link name = "upperArm">
         <visual>
            <geometry>
                <cylinder length="0.305" radius="0.035"/>
            </geometry>
            <material name="red">
                <!--color rgba="0 .8 0 1"/-->
             </material>
        </visual>

    </link>

    <link name = "elbowlink">
        <visual>
            <geometry>
                <cylinder length="0.09" radius="0.0175"/>
            </geometry>
            <material name="green">
                <!--color rgba="1 1 1 1"/-->
            </material>
        </visual>

    </link>

    <link name = "foreArm">
        <visual>
            <geometry>
                <cylinder length="0.25" radius="0.035"/>
            </geometry>
            <material name="blue">
                <!--color rgba="0 0 .5 1"/-->
            </material>
        </visual>


    </link>

    <link name = "wristlink">
        <visual>
            <geometry>
                <cylinder length="0.09" radius="0.01"/>
            </geometry>
            <material name="red">
                <!--color rgba="0 0 .7 1"/-->
            </material>
        </visual>

    </link>

    <link name = "tooltip">
        <visual>
            <geometry>
                <box size="0.035 0.16 0.02"/>
            </geometry>
            <material name="blue">
                <!--color rgba="0 0.5 8 1"/-->
            </material>
        </visual>

    </link>


    <joint name = "SA" type = "continuous">
        <parent link = "shoulderbase"/>
        <child link = "shoulderlinkab"/>
        <origin xyz = "0.5 0 0" rpy = "1.57 0 0"  />
        <axis xyz = "0 0 1" />
    </joint>

    <joint name = "SF" type = "continuous">
        <parent link = "shoulderlinkab"   />
        <child link = "shoulderlinkfl"    />
        <origin xyz = "0 0 -0.0925" rpy = "0 1.57 0"  />
        <axis xyz = "0 0 1" />
    </joint>

    <joint name = "AR" type = "continuous">
        <parent link = "shoulderlinkfl"   />
        <child link = "upperArm"    />
        <origin xyz = "0 -0.195 0" rpy = "1.57 0 0"  />
        <axis xyz = "0 0 1" />
    </joint>



    <joint name = "EF" type = "continuous">
        <parent link = "upperArm"   />
        <child link = "elbowlink"    />
        <origin xyz = "0 0 0.17" rpy = "-1.57 0 0"  />
        <axis xyz = "0 0 1" />
    </joint>

    <joint name = "WA" type = "continuous">
        <parent link = "elbowlink"   />
        <child link = "foreArm"    />
        <origin xyz = "0 -0.1425 0" rpy = "1.57 0 0"  />
        <axis xyz = "0 0 1" />
    </joint>

    <joint name = "WF" type = "continuous">
        <parent link = "foreArm"   />
        <child link = "wristlink"    />
        <origin xyz = "0 0 0.135" rpy = "-1.57 0 0"  />
        <axis xyz = "0 0 1" />
    </joint>

    <joint name = "PS" type = "continuous">
        <parent link = "wristlink"   />
        <child link = "tooltip"    />
        <origin xyz = "0 0 0" rpy = "0 1.57 0"  />
        <axis xyz = "0 0 1" />
    </joint>

</robot>
